Workbook
Name Company: INPUTS!$B$3
Name FYE: INPUTS!$H$3
Name Subheader: INPUTS!$K$3
Name TTS: TTS!$A$1

Sheet TTS
C7: Online Training: | D7: Training The Street's online training delivers the same high-powered materials | F7: Training The Street, Inc.
C8: ● Corporate Valuation | D8: and instruction style featured at live seminars in an innovative combination of | F8: 275 Madison Avenue Suite 1201
C9: ● Excel Best Practices | D9: video and dynamic Excel modeling drills. Our content is designed to equip or | F9: New York, NY 10016 USA
C10: ● Financial Modeling | D10: enhance your corporate valuation and financial modeling skills to best prepare | F10: Tel: +1 (800) 887-1320 (in the United States)
C11: ● Merger Modeling | D11: you for an interview, a new profession or a specific job function. | F11: +1 (704) 927-9688 (outside the United States)
C12: ● LBO Modeling | D12: http://www.trainingthestreet.com/ | F12: Fax:+1 (704) 547-3261
C15: Live Training: | D15: Corporate Valuation and Financial Modeling workshops ideal for industry | F15: Email: info@trainingthestreet.com
C16: Public Courses, | D16: professionals, students and prospective new hires.
C17: Evening & Weekend | D17: http://trainingthestreet.com/public_courses/course-calendar/
C18: Classes | D18: Public Comparables, Acquisition Comparables, Financial Modeling
D19: Discounted Cash Flow, Merger Modeling, Leveraged Buyouts
C22: TTS Macros List? | D22: Do you want us to send you our latest updates?
D23: http://trainingthestreet.com/macros/

Sheet INPUTS
Q1: x
B2: Company Name | H2: Last Fiscal Year End | K2: Subheader | Q2: x
B3: Sample Company | H3: 42369 | K3: Dollars in millions, except per share | Q3: x
Q4: x
Q5: x
A7: x | B7: END

Sheet Overview
Q1: x
Q2: x
Q3: x
Q4: x
Q5: x
B22: ="Discounted Cash Flow Analysis for "&Company -> Discounted Cash Flow Analysis for Sample Company | T22: The Methodology and Steps
B23: =Subheader -> Dollars in millions, except per share
P25: =I27&" - "&N27 -> 2015 - 2020
G26: Historical | J26: Projected | P26: CAGR
G27: =H27-1 -> 2013 | H27: =I27-1 -> 2014 | I27: =YEAR(FYE) -> 2015 | J27: =I27+1 -> 2016 | K27: =J27+1 -> 2017 | L27: =K27+1 -> 2018 | M27: =L27+1 -> 2019 | N27: =M27+1 -> 2020
A29: x | B29: Sales | G29: ='DCF Solution'!G29 -> 4666 | H29: ='DCF Solution'!H29 -> 4791.9 | I29: ='DCF Solution'!I29 -> 4988.1 | J29: =I29*(1+J51) -> 5187.624 | K29: =J29*(1+K51) -> 5395.129 | L29: =K29*(1+L51) -> 5610.9341 | M29: =L29*(1+M51) -> 5835.3715 | N29: =M29*(1+N51) -> 6068.7863 | P29: =RATE($N$27-$I$27,0,I29,-N29) -> 0.04
B30: Cost of goods sold | G30: ='DCF Solution'!G30 -> 3498.8 | H30: ='DCF Solution'!H30 -> 3767.7 | I30: ='DCF Solution'!I30 -> 3893.1 | J30: =J29*J52 -> 4046.3467 | K30: =K29*K52 -> 4202.8055 | L30: =L29*L52 -> 4365.3067 | M30: =M29*M52 -> 4534.0836 | N30: =N29*N52 -> 4709.3782
B31: Gross profit | G31: =G29-G30 -> 1167.2 | H31: =H29-H30 -> 1024.2 | I31: =I29-I30 -> 1095 | J31: =J29-J30 -> 1141.2773 | K31: =K29-K30 -> 1192.3235 | L31: =L29-L30 -> 1245.6274 | M31: =M29-M30 -> 1301.2878 | N31: =N29-N30 -> 1359.4081 | P31: =RATE($N$27-$I$27,0,I31,-N31) -> 0.04420832
B33: Selling, general & administrative | G33: ='DCF Solution'!G33 -> 316 | H33: ='DCF Solution'!H33 -> 306.1 | I33: ='DCF Solution'!I33 -> 280.3 | J33: =J29*J53 -> 290.50694 | K33: =K29*K53 -> 302.12722 | L33: =L29*L53 -> 314.21231 | M33: =M29*M53 -> 326.7808 | N33: =N29*N53 -> 339.85204
B34: EBITDA | G34: =G31-G33 -> 851.2 | H34: =H31-H33 -> 718.1 | I34: =I31-I33 -> 814.7 | J34: =J31-J33 -> 850.77034 | K34: =K31-K33 -> 890.19628 | L34: =L31-L33 -> 931.41506 | M34: =M31-M33 -> 974.50704 | N34: =N31-N33 -> 1019.5561 | P34: =RATE($N$27-$I$27,0,I34,-N34) -> 0.045881986
B35: Less: depreciation | G35: ='DCF Solution'!G35 -> -85 | H35: ='DCF Solution'!H35 -> -90 | I35: ='DCF Solution'!I35 -> -115.1 | J35: =J56*J42 -> -127.09679 | K35: =K56*K42 -> -132.85505 | L35: =L56*L42 -> -138.87062 | M35: =M56*M42 -> -145.15487 | N35: =N56*N42 -> -151.71966
B36: Less: amortization | G36: ='DCF Solution'!G36 -> -0.5 | H36: ='DCF Solution'!H36 -> -1.9 | I36: ='DCF Solution'!I36 -> -3.4 | J36: =-J58 -> -4.5 | K36: =-K58 -> -4.6 | L36: =-L58 -> -4.7 | M36: =-M58 -> -4.8 | N36: =-N58 -> -4.9
B37: EBIT | G37: =SUM(G34:G36) -> 765.7 | H37: =SUM(H34:H36) -> 626.2 | I37: =SUM(I34:I36) -> 696.2 | J37: =SUM(J34:J36) -> 719.17355 | K37: =SUM(K34:K36) -> 752.74123 | L37: =SUM(L34:L36) -> 787.84444 | M37: =SUM(M34:M36) -> 824.55217 | N37: =SUM(N34:N36) -> 862.93645 | P37: =RATE($N$27-$I$27,0,I37,-N37) -> 0.04387611
B38: Less: taxes @ | E38: ='DCF Solution'!E38 -> 0.38 | G38: =-G37*$E$38 -> -290.966 | H38: =-H37*$E$38 -> -237.956 | I38: =-I37*$E$38 -> -264.556 | J38: =-J37*$E$38 -> -273.28595 | K38: =-K37*$E$38 -> -286.04167 | L38: =-L37*$E$38 -> -299.38089 | M38: =-M37*$E$38 -> -313.32983 | N38: =-N37*$E$38 -> -327.91585
A39: x | B39: Tax-effected EBIT | G39: =SUM(G37:G38) -> 474.734 | H39: =SUM(H37:H38) -> 388.244 | I39: =SUM(I37:I38) -> 431.644 | J39: =SUM(J37:J38) -> 445.8876 | K39: =SUM(K37:K38) -> 466.69956 | L39: =SUM(L37:L38) -> 488.46356 | M39: =SUM(M37:M38) -> 511.22235 | N39: =SUM(N37:N38) -> 535.0206 | P39: =RATE($N$27-$I$27,0,I39,-N39) -> 0.04387611
B41: Plus: depreciation & amortization | H41: =-(H35+H36) -> 91.9 | I41: =-(I35+I36) -> 118.5 | J41: =-(J35+J36) -> 131.59679 | K41: =-(K35+K36) -> 137.45505 | L41: =-(L35+L36) -> 143.57062 | M41: =-(M35+M36) -> 149.95487 | N41: =-(N35+N36) -> 156.61966
B42: Less: capital expenditures | H42: ='DCF Solution'!H42 -> -95.8 | I42: ='DCF Solution'!I42 -> -120.6 | J42: =-J55*J29 -> -129.6906 | K42: =-K55*K29 -> -134.87822 | L42: =-L55*L29 -> -140.27335 | M42: =-M55*M29 -> -145.88429 | N42: =-N55*N29 -> -151.71966
B43: Less: additions to intangibles | H43: ='DCF Solution'!H43 -> -2 | I43: ='DCF Solution'!I43 -> -4 | J43: =-J57 -> -5 | K43: =-K57 -> -5 | L43: =-L57 -> -5 | M43: =-M57 -> -5 | N43: =-N57 -> -5
B44: + / - Changes in working capital | H44: ='DCF Solution'!H44 -> -19.2 | I44: ='DCF Solution'!I44 -> -20 | J44: =J59*J29 -> -20.750496 | K44: =K59*K29 -> -21.580516 | L44: =L59*L29 -> -22.443736 | M44: =M59*M29 -> -23.341486 | N44: =N59*N29 -> -24.275145
A45: x | B45: Unlevered free cash flow | H45: =SUM(H39:H44) -> 363.144 | I45: =SUM(I39:I44) -> 405.544 | J45: =SUM(J39:J44) -> 422.04329 | K45: =SUM(K39:K44) -> 442.69587 | L45: =SUM(L39:L44) -> 464.31709 | M45: =SUM(M39:M44) -> 486.95144 | N45: =SUM(N39:N44) -> 510.64545 | P45: =RATE($N$27-$I$27,0,I45,-N45) -> 0.047167844
G48: Historical | J48: Projected
B49: Value Drivers | G49: =G27 -> 2013 | H49: =H27 -> 2014 | I49: =I27 -> 2015 | J49: =J27 -> 2016 | K49: =K27 -> 2017 | L49: =L27 -> 2018 | M49: =M27 -> 2019 | N49: =N27 -> 2020 | Q49: Step
C51: Sales growth | H51: =H29/G29-1 -> 0.026982426 | I51: =I29/H29-1 -> 0.040944093 | J51: ='DCF Solution'!J51 -> 0.04 | K51: =J51 -> 0.04 | L51: =K51 -> 0.04 | M51: =L51 -> 0.04 | N51: =M51 -> 0.04
C52: Cost of goods sold (as a % sales) | G52: =G30/G29 -> 0.74984998 | H52: =H30/H29 -> 0.78626432 | I52: =I30/I29 -> 0.78047754 | J52: ='DCF Solution'!J52 -> 0.78 | K52: =J52+$Q52 -> 0.779 | L52: =K52+$Q52 -> 0.778 | M52: =L52+$Q52 -> 0.777 | N52: =M52+$Q52 -> 0.776 | Q52: ='DCF Solution'!Q52 -> -0.001
C53: SG&A (as a % sales) | G53: =G33/G29 -> 0.067723961 | H53: =H33/H29 -> 0.063878629 | I53: =I33/I29 -> 0.056193741 | J53: ='DCF Solution'!J53 -> 0.056 | K53: =J53 -> 0.056 | L53: =K53 -> 0.056 | M53: =L53 -> 0.056 | N53: =M53 -> 0.056
C54: EBITDA margin | G54: =G34/G29 -> 0.18242606 | H54: =H34/H29 -> 0.14985705 | I54: =I34/I29 -> 0.16332872 | J54: =J34/J29 -> 0.164 | K54: =K34/K29 -> 0.165 | L54: =L34/L29 -> 0.166 | M54: =M34/M29 -> 0.167 | N54: =N34/N29 -> 0.168
C55: CapEx (as a % sales) | H55: =IF(H29=0,0,-H42/H29) -> 0.01999207 | I55: =IF(I29=0,0,-I42/I29) -> 0.024177543 | J55: ='DCF Solution'!J55 -> 0.025 | K55: =J55 -> 0.025 | L55: =K55 -> 0.025 | M55: =L55 -> 0.025 | N55: =M55 -> 0.025
C56: Depreciation (as a % of CapEx) | H56: =IF(H42=0,0,H35/H42) -> 0.9394572 | I56: =IF(I42=0,0,I35/I42) -> 0.95439469 | J56: ='DCF Solution'!J56 -> 0.98 | K56: =J56+$Q56 -> 0.985 | L56: =K56+$Q56 -> 0.99 | M56: =L56+$Q56 -> 0.995 | N56: =M56+$Q56 -> 1 | Q56: ='DCF Solution'!Q56 -> 0.005
C57: Additions to intangibles (amount) | H57: =-H43 -> 2 | I57: =-I43 -> 4 | J57: ='DCF Solution'!J57 -> 5 | K57: =J57 -> 5 | L57: =K57 -> 5 | M57: =L57 -> 5 | N57: =M57 -> 5
C58: Amortization (amount) | H58: =-H36 -> 1.9 | I58: =-I36 -> 3.4 | J58: ='DCF Solution'!J58 -> 4.5 | K58: =J58+$Q58 -> 4.6 | L58: =K58+$Q58 -> 4.7 | M58: =L58+$Q58 -> 4.8 | N58: =M58+$Q58 -> 4.9 | Q58: ='DCF Solution'!Q58 -> 0.1
C59: Changes in working capital (as a % of Sales) | H59: =IF(H29=0,0,H44/H29) -> -0.0040067614 | I59: =IF(I29=0,0,I44/I29) -> -0.0040095427 | J59: ='DCF Solution'!J59 -> -0.004 | K59: =J59 -> -0.004 | L59: =K59 -> -0.004 | M59: =L59 -> -0.004 | N59: =M59 -> -0.004
C61: Weighted average cost of capital | G61: ='DCF Solution'!G61 -> 0.08 | I61: Equity value per share
C62: Terminal growth of unlevered FCF | G62: ='DCF Solution'!G62 -> 0.03 | K62: Sales growth | Q62: COGS Step | R62: Sales Step
J63: =G74 -> 35.318422 | K63: ='DCF Solution'!K63 -> 0.03 | L63: =K63+$R$63 -> 0.035 | M63: =L63+$R$63 -> 0.04 | N63: =M63+$R$63 -> 0.045 | Q63: ='DCF Solution'!Q63 -> 0.003 | R63: ='DCF Solution'!R63 -> 0.005
C64: NPV of unlevered free cash flow | G64: =NPV(G61,J45:N45) -> 1844.3716 | J64: =J65-$Q$63 -> 0.768 | K64: 36.862752 | L64: 37.736745 | M64: 38.627 | N64: 39.533746
...

Sheet Steps 1-2
B1: =MID(CELL("filename",B1),FIND("]",CELL("filename",B1))+1,31)&": Input and Analyze Historical Fee Cash Flows" -> Steps 1-2: Input and Analyze Historical Fee Cash Flows | R1: TTS Help
R2: Step 1 | S2: =ADDRESS(ROW(G31),COLUMN(G31),4)& " = " -> G31 = | T2: =ADDRESS(ROW(G29),COLUMN(G29),4)&" - "&ADDRESS(ROW(G30),COLUMN(G30),4) -> G29 - G30 | V2: Gross Profit
C3: ="Step "&A31&": Input the Unlevered Free Cash Flow line items" -> Step 1: Input the Unlevered Free Cash Flow line items | J3: Cell Anchoring | S3: =ADDRESS(ROW(G34),COLUMN(G34),4)& " = " -> G34 = | T3: =ADDRESS(ROW(G31),COLUMN(G31),4)&" - "&ADDRESS(ROW(G33),COLUMN(G33),4) -> G31 - G33 | V3: EBITDA
D4: =" - Normalize Unlevered Free Cash Flow for any non-recurring items;" -> - Normalize Unlevered Free Cash Flow for any non-recurring items; | K4: Windows | L4: Mac | S4: =ADDRESS(ROW(G37),COLUMN(G37),4)& " = " -> G37 = | T4: ="SUM("&ADDRESS(ROW(G34),COLUMN(G34),4)&":"&ADDRESS(ROW(G36),COLUMN(G36),4)&")" -> SUM(G34:G36) | V4: EBIT
D5: be sure to source your adjustments | J5: Edit Cell | K5: F2 | L5: Ctl+U | S5: =ADDRESS(ROW(G39),COLUMN(G39),4)& " = " -> G39 = | T5: ="SUM("&ADDRESS(ROW(G37),COLUMN(G37),4)&":"&ADDRESS(ROW(G38),COLUMN(G38),4)&")" -> SUM(G37:G38) | V5: Tax-effected EBIT
D6: =" - Remember to anchor the column for the tax rate ($"&ADDRESS(ROW(E38),COLUMN(E38),4)&")" -> - Remember to anchor the column for the tax rate ($E38) | J6: Anchor Cell | K6: F4 | L6: Cmd+T | S6: =ADDRESS(ROW(H45),COLUMN(H45),4)& " = " -> H45 = | T6: ="SUM("&ADDRESS(ROW(H39),COLUMN(H39),4)&":"&ADDRESS(ROW(H44),COLUMN(H44),4)&")" -> SUM(H39:H44) | V6: Unlevered FCF
R7: Step 2 | S7: =ADDRESS(ROW(H51),COLUMN(H51),4)& " = " -> H51 = | T7: =ADDRESS(ROW(H29),COLUMN(H29),4)&" / "&ADDRESS(ROW(G29),COLUMN(G29),4)&" - 1" -> H29 / G29 - 1 | V7: Sales Growth
C8: ="Step "&A51&": Calculate the historical ratios and growth rates" -> Step 2: Calculate the historical ratios and growth rates | J8: Assume cell B5 is copied to cell D7 | S8: =ADDRESS(ROW(H52),COLUMN(H52),4)& " = " -> H52 = | T8: =ADDRESS(ROW(H30),COLUMN(H30),4)&" / "&ADDRESS(ROW($H$29),COLUMN($H$29),4) -> H30 / H29 | V8: COGS (% of sales)
D9: - Historical ratios will serve as a guide for the projections | J9: Anchor Cell: $B$5 stays $B$5 | S9: =ADDRESS(ROW(H54),COLUMN(H54),4)& " = " -> H54 = | T9: =ADDRESS(ROW(H34),COLUMN(H34),4)&" / "&ADDRESS(ROW($H$29),COLUMN($H$29),4) -> H34 / H29 | V9: EBITDA Margin
D10: - Format cells as you go along | J10: Anchor Row: B$5 changes to D$5
J11: Anchor Column: $B5 changes to $B7
J12: Relative Reference: B5 changes to D7
B22: ="Discounted Cash Flow Analysis for "&Company -> Discounted Cash Flow Analysis for Sample Company
B23: =Subheader -> Dollars in millions, except per share
P25: =I27&" - "&N27 -> 2015 - 2020
G26: Historical | J26: Projected | P26: CAGR
G27: =H27-1 -> 2013 | H27: =I27-1 -> 2014 | I27: =YEAR(FYE) -> 2015 | J27: =I27+1 -> 2016 | K27: =J27+1 -> 2017 | L27: =K27+1 -> 2018 | M27: =L27+1 -> 2019 | N27: =M27+1 -> 2020
B29: Sales | G29: 4666 | H29: 4791.9 | I29: 4988.1 | P29: 1e-06
B30: Cost of goods sold | G30: 3498.8 | H30: 3767.7 | I30: 3893.1
A31: 1 | B31: Gross profit | G31: 1e-06 | H31: 1e-06 | I31: 1e-06 | P31: 1e-06
B33: Selling, general & administrative | G33: 316 | H33: 306.1 | I33: 280.3
A34: 1 | B34: EBITDA | G34: 1e-06 | H34: 1e-06 | I34: 1e-06 | P34: 1e-06
B35: Less: depreciation | G35: -85 | H35: -90 | I35: -115.1
B36: Less: amortization | G36: -0.5 | H36: -1.9 | I36: -3.4
A37: 1 | B37: EBIT | G37: 1e-06 | H37: 1e-06 | I37: 1e-06 | P37: 1e-06
B38: Less: taxes @ | E38: 0.38 | G38: =-G37*$E38 -> -3.8e-07 | H38: =-H37*$E38 -> -3.8e-07 | I38: =-I37*$E38 -> -3.8e-07
A39: 1 | B39: Tax-effected EBIT | G39: 1e-06 | H39: 1e-06 | I39: 1e-06 | P39: 1e-06
B41: Plus: depreciation & amortization | H41: =-(H35+H36) -> 91.9 | I41: =-(I35+I36) -> 118.5 | S41: Cell Anchoring
B42: Less: capital expenditures | H42: -95.8 | I42: -120.6 | T42: Windows | U42: Mac
B43: Less: additions to intangibles | H43: -2 | I43: -4 | S43: Edit Cell | T43: F2 | U43: Ctl+U
B44: + / - Changes in working capital | H44: -19.2 | I44: -20 | S44: Anchor Cell | T44: F4 | U44: Cmd+T
A45: 1 | B45: Unlevered free cash flow | H45: 1e-06 | I45: 1e-06 | P45: 1e-06
G48: Historical | J48: Projected
B49: Value Drivers | G49: =G27 -> 2013 | H49: =H27 -> 2014 | I49: =I27 -> 2015 | J49: =J27 -> 2016 | K49: =K27 -> 2017 | L49: =L27 -> 2018 | M49: =M27 -> 2019 | N49: =N27 -> 2020 | Q49: Step
A51: 2 | C51: Sales growth | H51: 1e-06 | I51: 1e-06 | J51: 0.04
A52: 2 | C52: Cost of goods sold (as a % sales) | G52: =G30/G29 -> 0.74984998 | H52: 1e-06 | I52: 1e-06 | J52: 0.78 | Q52: -0.001
C53: SG&A (as a % sales) | G53: =G33/G29 -> 0.067723961 | H53: =H33/H29 -> 0.063878629 | I53: =I33/I29 -> 0.056193741 | J53: 0.056
A54: 2 | C54: EBITDA margin | G54: =G34/G29 -> 2.1431633e-10 | H54: 1e-06 | I54: 1e-06
C55: CapEx (as a % sales) | H55: =IF(H29=0,0,-H42/H29) -> 0.01999207 | I55: =IF(I29=0,0,-I42/I29) -> 0.024177543 | J55: 0.025 | K55: =J55 -> 0.025 | L55: =K55 -> 0.025 | M55: =L55 -> 0.025 | N55: =M55 -> 0.025
C56: Depreciation (as a % of CapEx) | H56: =IF(H42=0,0,H35/H42) -> 0.9394572 | I56: =IF(I42=0,0,I35/I42) -> 0.95439469 | J56: 0.98 | K56: =J56 -> 0.98 | L56: =K56 -> 0.98 | M56: =L56 -> 0.98 | N56: =M56 -> 0.98 | Q56: 0.005
...

Sheet Steps 3-6
B1: =MID(CELL("filename",B1),FIND("]",CELL("filename",B1))+1,31)&": Forecast down to EBITDA" -> Steps 3-6: Forecast down to EBITDA | R1: TTS Help
R2: Step 3 | S2: =ADDRESS(ROW(K51),COLUMN(K51),4)& " = " -> K51 = | T2: =ADDRESS(ROW(J51),COLUMN(J51),4) -> J51 | V2: Sales Growth Flatline
C3: ="Step "&A29&": Forecast net sales for the projected years" -> Step 3: Forecast net sales for the projected years | J3: ="Step "&RIGHT(A52,1)&": Add ''steps'' to your assumptions" -> Step 5: Add ''steps'' to your assumptions | S3: =ADDRESS(ROW(J29),COLUMN(J29),4)& " = " -> J29 = | T3: =ADDRESS(ROW(I29),COLUMN(I29),4)&" * (1 + "&ADDRESS(ROW(J51),COLUMN(J51),4)&")" -> I29 * (1 + J51) | V3: =J27&" Sales" -> 2016 Sales
D4: - Drivers: projected annual sales growth rates | J4: - Alternative to having all BLUE inputs | R4: Step 4 | S4: =ADDRESS(ROW(K52),COLUMN(K52),4)& " = " -> K52 = | T4: =ADDRESS(ROW(J52),COLUMN(J52),4) -> J52 | V4: COGS Flatline
D5: - Sources: Management numbers, research or historical performance | J5: - Often used if increasing or decreasing an | S5: =ADDRESS(ROW(J30),COLUMN(J30),4)& " = " -> J30 = | T5: =ADDRESS(ROW(J29),COLUMN(J29),4)&" * "&ADDRESS(ROW(J52),COLUMN(J52),4) -> J29 * J52 | V5: =J27&" COGS" -> 2016 COGS
D6: Are the assumptions reasonable and defensible? | J6: assumption by a constant amount | S6: =ADDRESS(ROW(K53),COLUMN(K53),4)& " = " -> K53 = | T6: =ADDRESS(ROW(J53),COLUMN(J53),4) -> J53 | V6: SG&A Flatline
D7: - Footnote your sources | S7: =ADDRESS(ROW(J33),COLUMN(J33),4)& " = " -> J33 = | T7: =ADDRESS(ROW(J29),COLUMN(J29),4)&" * "&ADDRESS(ROW(J53),COLUMN(J53),4) -> J29 * J53 | V7: =J27&" SG&A" -> 2016 SG&A
R8: Step 5 | S8: =ADDRESS(ROW(K52),COLUMN(K52),4)& " = " -> K52 = | T8: =ADDRESS(ROW(J52),COLUMN(J52),4)&" + $"&ADDRESS(ROW(Q52),COLUMN(Q52),4) -> J52 + $Q52 | V8: COGS Flatline + Step
C9: ="Step "&A30&": Project future operating expenses" -> Step 4: Project future operating expenses | J9: ="Step "&A34&": Calculate totals" -> Step 6: Calculate totals | R9: Step 6 | S9: =ADDRESS(ROW(J31),COLUMN(J31),4)& " = " -> J31 = | T9: =ADDRESS(ROW(J29),COLUMN(J29),4)&" - "&ADDRESS(ROW(J30),COLUMN(J30),4) -> J29 - J30 | V9: Gross Profit
D10: - Drivers: margin assumptions for future operating expenses | J10: - Calculate totals down to EBITDA, but leave | S10: =ADDRESS(ROW(J34),COLUMN(J34),4)& " = " -> J34 = | T10: =ADDRESS(ROW(J31),COLUMN(J31),4)&" - "&ADDRESS(ROW(J33),COLUMN(J33),4) -> J31 - J33 | V10: EBITDA
D11: - Sources: Management numbers, research or historical performance | J11: D&A blank for now | S11: J54 = | T11: J34 / J29 | V11: EBITDA Margin
D12: Are the assumptions reasonable and defensible? | J12: - Calculate the EBITDA Margin
B22: ="Discounted Cash Flow Analysis for "&Company -> Discounted Cash Flow Analysis for Sample Company
B23: =Subheader -> Dollars in millions, except per share
P25: =I27&" - "&N27 -> 2015 - 2020
G26: Historical | J26: Projected | P26: CAGR
G27: =H27-1 -> 2013 | H27: =I27-1 -> 2014 | I27: =YEAR(FYE) -> 2015 | J27: =I27+1 -> 2016 | K27: =J27+1 -> 2017 | L27: =K27+1 -> 2018 | M27: =L27+1 -> 2019 | N27: =M27+1 -> 2020
A29: 3 | B29: Sales | G29: 4666 | H29: 4791.9 | I29: 4988.1 | J29: 1e-06 | K29: 1e-06 | L29: 1e-06 | M29: 1e-06 | N29: 1e-06 | P29: 1e-06
A30: 4 | B30: Cost of goods sold | G30: 3498.8 | H30: 3767.7 | I30: 3893.1 | J30: 1e-06 | K30: 1e-06 | L30: 1e-06 | M30: 1e-06 | N30: 1e-06
A31: 6 | B31: Gross profit | G31: =G29-G30 -> 1167.2 | H31: =H29-H30 -> 1024.2 | I31: =I29-I30 -> 1095 | J31: 1e-06 | K31: 1e-06 | L31: 1e-06 | M31: 1e-06 | N31: 1e-06 | P31: 1e-06
A33: 4 | B33: Selling, general & administrative | G33: 316 | H33: 306.1 | I33: 280.3 | J33: 1e-06 | K33: 1e-06 | L33: 1e-06 | M33: 1e-06 | N33: 1e-06
A34: 6 | B34: EBITDA | G34: =G31-G33 -> 851.2 | H34: =H31-H33 -> 718.1 | I34: =I31-I33 -> 814.7 | J34: 1e-06 | K34: 1e-06 | L34: 1e-06 | M34: 1e-06 | N34: 1e-06 | P34: 1e-06
B35: Less: depreciation | G35: -85 | H35: -90 | I35: -115.1
B36: Less: amortization | G36: -0.5 | H36: -1.9 | I36: -3.4
B37: EBIT | G37: =SUM(G34:G36) -> 765.7 | H37: =SUM(H34:H36) -> 626.2 | I37: =SUM(I34:I36) -> 696.2 | P37: 1e-06
B38: Less: taxes @ | E38: 0.38 | G38: =-G37*$E38 -> -290.966 | H38: =-H37*$E38 -> -237.956 | I38: =-I37*$E38 -> -264.556
B39: Tax-effected EBIT | G39: =SUM(G37:G38) -> 474.734 | H39: =SUM(H37:H38) -> 388.244 | I39: =SUM(I37:I38) -> 431.644 | P39: 1e-06
B41: Plus: depreciation & amortization | H41: =-(H35+H36) -> 91.9 | I41: =-(I35+I36) -> 118.5
B42: Less: capital expenditures | H42: -95.8 | I42: -120.6
B43: Less: additions to intangibles | H43: -2 | I43: -4
B44: + / - Changes in working capital | H44: -19.2 | I44: -20
B45: Unlevered free cash flow | H45: =SUM(H39:H44) -> 363.144 | I45: =SUM(I39:I44) -> 405.544 | P45: 1e-06
G48: Historical | J48: Projected
B49: Value Drivers | G49: =G27 -> 2013 | H49: =H27 -> 2014 | I49: =I27 -> 2015 | J49: =J27 -> 2016 | K49: =K27 -> 2017 | L49: =L27 -> 2018 | M49: =M27 -> 2019 | N49: =N27 -> 2020 | Q49: Step
A51: 3 | C51: Sales growth | H51: =H29/G29-1 -> 0.026982426 | I51: =I29/H29-1 -> 0.040944093 | J51: 0.04 | K51: 0.0001 | L51: 0.0001 | M51: 0.0001 | N51: 0.0001 | S51: Cell Anchoring
A52: 4,5 | C52: Cost of goods sold (as a % sales) | G52: =G30/G29 -> 0.74984998 | H52: =H30/H29 -> 0.78626432 | I52: =I30/I29 -> 0.78047754 | J52: 0.78 | K52: 0.0001 | L52: 0.0001 | M52: 0.0001 | N52: 0.0001 | Q52: -0.001 | T52: Windows | U52: Mac
A53: 4 | C53: SG&A (as a % sales) | G53: =G33/G29 -> 0.067723961 | H53: =H33/H29 -> 0.063878629 | I53: =I33/I29 -> 0.056193741 | J53: 0.056 | K53: 0.0001 | L53: 0.0001 | M53: 0.0001 | N53: 0.0001 | S53: Edit Cell | T53: F2 | U53: Ctl+U
A54: 6 | C54: EBITDA margin | G54: =G34/G29 -> 0.18242606 | H54: =H34/H29 -> 0.14985705 | I54: =I34/I29 -> 0.16332872 | J54: 0.0001 | K54: 0.0001 | L54: 0.0001 | M54: 0.0001 | N54: 0.0001 | S54: Anchor Cell | T54: F4 | U54: Cmd+T
C55: CapEx (as a % sales) | H55: =IF(H29=0,0,-H42/H29) -> 0.01999207 | I55: =IF(I29=0,0,-I42/I29) -> 0.024177543 | J55: 0.025 | K55: =J55 -> 0.025 | L55: =K55 -> 0.025 | M55: =L55 -> 0.025 | N55: =M55 -> 0.025
C56: Depreciation (as a % of CapEx) | H56: =IF(H42=0,0,H35/H42) -> 0.9394572 | I56: =IF(I42=0,0,I35/I42) -> 0.95439469 | J56: 0.98 | K56: =J56 -> 0.98 | L56: =K56 -> 0.98 | M56: =L56 -> 0.98 | N56: =M56 -> 0.98 | Q56: 0.005
...

Sheet Steps 7-10
B1: =MID(CELL("filename",B1),FIND("]",CELL("filename",B1))+1,31)&": Forcast Fixed Assets, Intangible Assets and Working Capital" -> Steps 7-10: Forcast Fixed Assets, Intangible Assets and Working Capital | R1: TTS Help
R2: Step 7 | S2: =ADDRESS(ROW(J42),COLUMN(J42),4)& " = " -> J42 = | T2: =ADDRESS(ROW(J29),COLUMN(J30),4)&" * "& ADDRESS(ROW(J55),COLUMN(J55),4) -> J29 * J55 | V2: =J27&" Capex" -> 2016 Capex
C3: ="Step "&A35&": Project Capital Expenditures & Depreciation" -> Step 7: Project Capital Expenditures & Depreciation | J3: ="Step "&RIGHT(A44,1)&": Project future working capital requirements" -> Step 9: Project future working capital requirements | S3: =ADDRESS(ROW(J35),COLUMN(J35),4)& " = " -> J35 = | T3: =ADDRESS(ROW(J42),COLUMN(J42),4)&" * "&ADDRESS(ROW(J56),COLUMN(J56),4) -> J42 * J56 | V3: =J27&" Depreciation" -> 2016 Depreciation
D4: - Sources: Management numbers, research or historical | J4: - Common to see this driven by either % of sales or dollar amount | R4: Step 8 | S4: =ADDRESS(ROW(J43),COLUMN(J43),4)& " = " -> J43 = | T4: ="- "&ADDRESS(ROW(J57),COLUMN(J57),4) -> - J57 | V4: =J27&" Additions to Intangibles" -> 2016 Additions to Intangibles
D5: - CapEx as % sales is a common driver if no guidance is available | J5: - Review historicals, research or management expectations | S5: =ADDRESS(ROW(J36),COLUMN(J36),4)& " = " -> J36 = | T5: ="- "&ADDRESS(ROW(J58),COLUMN(J58),4) -> - J58 | V5: =J27&" Amortization" -> 2016 Amortization
D6: Also popular to see based on reasonable “hard dollars” or other | S6: =ADDRESS(ROW(J41),COLUMN(J41),4)& " = " -> J41 = | T6: ="-("&ADDRESS(ROW(J35),COLUMN(J35),4)&" + "&ADDRESS(ROW(J36),COLUMN(J36),4)&")" -> -(J35 + J36) | V6: =J27&" Depreciation & Amortization" -> 2016 Depreciation & Amortization
D7: appropriate drivers | J7: ="Step "&A45&": Calculate Unlevered Free Cash Flow" -> Step 10: Calculate Unlevered Free Cash Flow | R7: Step 9 | S7: =ADDRESS(ROW(J44),COLUMN(J44),4)& " = " -> J44 = | T7: =ADDRESS(ROW(J29),COLUMN(J29),4)&" * "&ADDRESS(ROW(J59),COLUMN(J59),4) -> J29 * J59 | V7: =J27&" Change in Working Capital" -> 2016 Change in Working Capital
D8: - Choose a reasonable method to project depreciation: | J8: - Calculate totals | R8: Step 10 | S8: =ADDRESS(ROW(J37),COLUMN(J37),4)& " = " -> J37 = | T8: ="SUM("&ADDRESS(ROW(J34),COLUMN(J34),4)&":"&ADDRESS(ROW(J36),COLUMN(J36),4)&")" -> SUM(J34:J36) | V8: EBIT
D9: As a % of CapEx, as a % of sales or “hard dollars” | J9: - Calculate taxes | S9: =ADDRESS(ROW(J38),COLUMN(J38),4)& " = " -> J38 = | T9: ="-"&ADDRESS(ROW(J37),COLUMN(J37),4)&" * $"&ADDRESS(ROW(E38),COLUMN(E38),4) -> -J37 * $E38 | V9: Taxes
D10: - The trend and relationship between CapEx and depreciation | J10: - Calculate Compound Annual Growth Rates (CAGRs) | S10: =ADDRESS(ROW(J39),COLUMN(J39),4)& " = " -> J39 = | T10: ="SUM("&ADDRESS(ROW(J37),COLUMN(J37),4)&":"&ADDRESS(ROW(J38),COLUMN(J38),4)&")" -> SUM(J37:J38) | V10: Tax-effected EBIT
D11: is key. Use step function to move toward "Maintenance Capex" | J11: - Rate Function: RATE(nper,pmt, pv, [fv]) | S11: =ADDRESS(ROW(J45),COLUMN(J45),4)& " = " -> J45 = | T11: ="SUM("&ADDRESS(ROW(J39),COLUMN(J39),4)&":"&ADDRESS(ROW(J44),COLUMN(J44),4)&")" -> SUM(J39:J44) | V11: Unlevered FCF
J12: - Formula: | L12: (FV / PV) (1/n) -1 | S12: =ADDRESS(ROW(P29),COLUMN(P29),4)& " = " -> P29 = | T12: ="RATE(5,0,-"&ADDRESS(ROW(I29),COLUMN(I29),4)&","&ADDRESS(ROW(N29),COLUMN(N29),4)&")" -> RATE(5,0,-I29,N29) | V12: =P25&" Sales CAGR" -> 2015 - 2020 Sales CAGR
C13: ="Step "&A43&": Project Additions to Intangibles & Amortization" -> Step 8: Project Additions to Intangibles & Amortization | J13: - Add right border on the last historical year as a "divider"
C14: - Is the company purchasing new intangibles?
C15: - Common to see this driven by either % of sales or dollar amount
C16: - Review historicals, research or management expectations
C17: - Examine the footnotes for disclosure on amortization expense
C18: - Add back sum of D&A because it is a non-cash expense
B22: ="Discounted Cash Flow Analysis for "&Company -> Discounted Cash Flow Analysis for Sample Company
B23: =Subheader -> Dollars in millions, except per share
P25: =I27&" - "&N27 -> 2015 - 2020
G26: Historical | J26: Projected | P26: CAGR
G27: =H27-1 -> 2013 | H27: =I27-1 -> 2014 | I27: =YEAR(FYE) -> 2015 | J27: =I27+1 -> 2016 | K27: =J27+1 -> 2017 | L27: =K27+1 -> 2018 | M27: =L27+1 -> 2019 | N27: =M27+1 -> 2020
B29: Sales | G29: 4666 | H29: 4791.9 | I29: 4988.1 | J29: =I29*(1+J51) -> 5187.624 | K29: =J29*(1+K51) -> 5395.129 | L29: =K29*(1+L51) -> 5610.9341 | M29: =L29*(1+M51) -> 5835.3715 | N29: =M29*(1+N51) -> 6068.7863 | P29: 1e-06
B30: Cost of goods sold | G30: 3498.8 | H30: 3767.7 | I30: 3893.1 | J30: =J29*J52 -> 4046.3467 | K30: =K29*K52 -> 4202.8055 | L30: =L29*L52 -> 4365.3067 | M30: =M29*M52 -> 4534.0836 | N30: =N29*N52 -> 4709.3782
B31: Gross profit | G31: =G29-G30 -> 1167.2 | H31: =H29-H30 -> 1024.2 | I31: =I29-I30 -> 1095 | J31: =J29-J30 -> 1141.2773 | K31: =K29-K30 -> 1192.3235 | L31: =L29-L30 -> 1245.6274 | M31: =M29-M30 -> 1301.2878 | N31: =N29-N30 -> 1359.4081 | P31: 1e-06
B33: Selling, general & administrative | G33: 316 | H33: 306.1 | I33: 280.3 | J33: =J29*J53 -> 290.50694 | K33: =K29*K53 -> 302.12722 | L33: =L29*L53 -> 314.21231 | M33: =M29*M53 -> 326.7808 | N33: =N29*N53 -> 339.85204
B34: EBITDA | G34: =G31-G33 -> 851.2 | H34: =H31-H33 -> 718.1 | I34: =I31-I33 -> 814.7 | J34: =J31-J33 -> 850.77034 | K34: =K31-K33 -> 890.19628 | L34: =L31-L33 -> 931.41506 | M34: =M31-M33 -> 974.50704 | N34: =N31-N33 -> 1019.5561 | P34: 1e-06
A35: 7 | B35: Less: depreciation | G35: -85 | H35: -90 | I35: -115.1 | J35: 1e-06 | K35: 1e-06 | L35: 1e-06 | M35: 1e-06 | N35: 1e-06
A36: 8 | B36: Less: amortization | G36: -0.5 | H36: -1.9 | I36: -3.4 | J36: 1e-06 | K36: 1e-06 | L36: 1e-06 | M36: 1e-06 | N36: 1e-06
A37: 10 | B37: EBIT | G37: =SUM(G34:G36) -> 765.7 | H37: =SUM(H34:H36) -> 626.2 | I37: =SUM(I34:I36) -> 696.2 | J37: 1e-06 | K37: 1e-06 | L37: 1e-06 | M37: 1e-06 | N37: 1e-06 | P37: 1e-06
A38: 10 | B38: Less: taxes @ | E38: 0.38 | G38: =-G37*$E$38 -> -290.966 | H38: =-H37*$E$38 -> -237.956 | I38: =-I37*$E$38 -> -264.556 | J38: 1e-06 | K38: 1e-06 | L38: 1e-06 | M38: 1e-06 | N38: 1e-06
A39: 10 | B39: Tax-effected EBIT | G39: =SUM(G37:G38) -> 474.734 | H39: =SUM(H37:H38) -> 388.244 | I39: =SUM(I37:I38) -> 431.644 | J39: 1e-06 | K39: 1e-06 | L39: 1e-06 | M39: 1e-06 | N39: 1e-06 | P39: 1e-06
A41: 7,8 | B41: Plus: depreciation & amortization | H41: =-(H35+H36) -> 91.9 | I41: =-(I35+I36) -> 118.5 | J41: 1e-06 | K41: 1e-06 | L41: 1e-06 | M41: 1e-06 | N41: 1e-06
A42: 7 | B42: Less: capital expenditures | H42: -95.8 | I42: -120.6 | J42: 1e-06 | K42: 1e-06 | L42: 1e-06 | M42: 1e-06 | N42: 1e-06
A43: 8 | B43: Less: additions to intangibles | H43: -2 | I43: -4 | J43: 1e-06 | K43: 1e-06 | L43: 1e-06 | M43: 1e-06 | N43: 1e-06
A44: 9 | B44: + / - Changes in working capital | H44: -19.2 | I44: -20 | J44: 1e-06 | K44: 1e-06 | L44: 1e-06 | M44: 1e-06 | N44: 1e-06
A45: 10 | B45: Unlevered free cash flow | H45: =SUM(H39:H44) -> 363.144 | I45: =SUM(I39:I44) -> 405.544 | J45: 1e-06 | K45: 1e-06 | L45: 1e-06 | M45: 1e-06 | N45: 1e-06 | P45: 1e-06
G48: Historical | J48: Projected
B49: Value Drivers | G49: =G27 -> 2013 | H49: =H27 -> 2014 | I49: =I27 -> 2015 | J49: =J27 -> 2016 | K49: =K27 -> 2017 | L49: =L27 -> 2018 | M49: =M27 -> 2019 | N49: =N27 -> 2020 | Q49: Step
...

Sheet Steps 11-17
B1: =MID(CELL("filename",B1),FIND("]",CELL("filename",B1))+1,31)&": Calculate the intrinsic value of the unlevered free cash flows" -> Steps 11-17: Calculate the intrinsic value of the unlevered free cash flows | R1: TTS Help
R2: 11 | S2: =ADDRESS(ROW(G64),COLUMN(G64),4)& " = " -> G64 = | T2: ="NPV("&ADDRESS(ROW(G61),COLUMN(G61),4)&","&ADDRESS(ROW(J45),COLUMN(J45),4)&":"&ADDRESS(ROW(N45),COLUMN(N45),4)&")" -> NPV(G61,J45:N45) | W2: NPV of Unlevered FCF
C3: ="Step "&A64&": Calculate the net present value of the unlevered free cash flow" -> Step 11: Calculate the net present value of the unlevered free cash flow | K3: ="Step "&A66&": Calculate the present value of terminal value" -> Step 13: Calculate the present value of terminal value | R3: 12 | S3: =ADDRESS(ROW(G65),COLUMN(G65),4)& " = " -> G65 = | T3: =ADDRESS(ROW(N45),COLUMN(N45),4)&" * (1 + "&ADDRESS(ROW(G62),COLUMN(G62),4)&") / ("&ADDRESS(ROW(G61),COLUMN(G61),4)&" - "&ADDRESS(ROW(G62),COLUMN(G62),4)&")" -> N45 * (1 + G62) / (G61 - G62) | W3: Terminal Value
D4: - Estimate the Weighted Average Cost of Capital (WACC) | K4: - Use the formula builder and the PV function | R4: 13 | S4: =ADDRESS(ROW(G66),COLUMN(G66),4)& " = " -> G66 = | T4: ="PV("&ADDRESS(ROW(G61),COLUMN(G61),4)&",5,0,-"&ADDRESS(ROW(G65),COLUMN(G65),4)&")" -> PV(G61,5,0,-G65) | W4: PV of Terminal Value
D5: WACC = Ke x | E5: E + Kd x (1 + T) x D | K5: - PV Function: PV(rate,nper, pmt, [fv]) | R5: 14 | S5: =ADDRESS(ROW(G67),COLUMN(G67),4)& " = " -> G67 = | T5: =ADDRESS(ROW(G64),COLUMN(G64),4)&" + "&ADDRESS(ROW(G66),COLUMN(G66),4) -> G64 + G66 | W5: Enterprise Value
E6: D + E | F6: D + E | R6: 15 | S6: =ADDRESS(ROW(G70),COLUMN(G70),4)& " = " -> G70 = | T6: ="SUM("&ADDRESS(ROW(G67),COLUMN(G67),4)&":"&ADDRESS(ROW(G69),COLUMN(G69),4)&")" -> SUM(G67:G69) | W6: Equity Value
D7: - Sources: Management, research or corporate finance theory | K7: ="Step "&A67&": Calculate the Enterprise Value" -> Step 14: Calculate the Enterprise Value | R7: 16 | S7: =ADDRESS(ROW(G74),COLUMN(G74),4)& " = " -> G74 = | T7: =ADDRESS(ROW(G70),COLUMN(G70),4)&" / "&ADDRESS(ROW(G72),COLUMN(G72),4) -> G70 / G72 | W7: Equity Value / Share
D8: - Calculate the net present value: | K8: - NPV of cash flows + PV of Terminal Value
D9: - NPV Function: NPV(rate,value1, value2, value3...)
D10: - Formula: | F10: CF1 + CF2 + … CFn | K10: ="Step "&A70&": Calculate the Equity Value" -> Step 15: Calculate the Equity Value
F11: (1+r)1 (1+r)2 (1+r)3 | K11: - Input the latest financial information
C12: ="Step "&A65&": Calculate the terminal value" -> Step 12: Calculate the terminal value | K12: - Equity Value = Enterprise Value + "Net Debt"
D13: - Assumes the business grows at a constant rate in perpetuity
G14: FCF = normalized free cash flow in Period N | K14: ="Step "&A74&": Calculate the Equity Value per share" -> Step 16: Calculate the Equity Value per share
D15: Terminal Value = FCFn x (1 + g) | G15: g = nominal perpetual growth rate | K15: - Divide equity value by the latest diluted share count
E16: (r - g) | G16: r = discount rate or WACC
K17: ="Step "&A63&": Sensitize the equity value per share" -> Step 17: Sensitize the equity value per share
B22: ="Discounted Cash Flow Analysis for "&Company -> Discounted Cash Flow Analysis for Sample Company
B23: =Subheader -> Dollars in millions, except per share
P25: =I27&" - "&N27 -> 2015 - 2020
G26: Historical | J26: Projected | P26: CAGR
G27: =H27-1 -> 2013 | H27: =I27-1 -> 2014 | I27: =YEAR(FYE) -> 2015 | J27: =I27+1 -> 2016 | K27: =J27+1 -> 2017 | L27: =K27+1 -> 2018 | M27: =L27+1 -> 2019 | N27: =M27+1 -> 2020
B29: Sales | G29: 4666 | H29: 4791.9 | I29: 4988.1 | J29: =I29*(1+J51) -> 5187.624 | K29: =J29*(1+K51) -> 5395.129 | L29: =K29*(1+L51) -> 5610.9341 | M29: =L29*(1+M51) -> 5835.3715 | N29: =M29*(1+N51) -> 6068.7863 | P29: =RATE($N$27-$I$27,0,I29,-N29) -> 0.04
B30: Cost of goods sold | G30: 3498.8 | H30: 3767.7 | I30: 3893.1 | J30: =J29*J52 -> 4046.3467 | K30: =K29*K52 -> 4202.8055 | L30: =L29*L52 -> 4365.3067 | M30: =M29*M52 -> 4534.0836 | N30: =N29*N52 -> 4709.3782
B31: Gross profit | G31: =G29-G30 -> 1167.2 | H31: =H29-H30 -> 1024.2 | I31: =I29-I30 -> 1095 | J31: =J29-J30 -> 1141.2773 | K31: =K29-K30 -> 1192.3235 | L31: =L29-L30 -> 1245.6274 | M31: =M29-M30 -> 1301.2878 | N31: =N29-N30 -> 1359.4081 | P31: =RATE($N$27-$I$27,0,I31,-N31) -> 0.04420832
B33: Selling, general & administrative | G33: 316 | H33: 306.1 | I33: 280.3 | J33: =J29*J53 -> 290.50694 | K33: =K29*K53 -> 302.12722 | L33: =L29*L53 -> 314.21231 | M33: =M29*M53 -> 326.7808 | N33: =N29*N53 -> 339.85204
B34: EBITDA | G34: =G31-G33 -> 851.2 | H34: =H31-H33 -> 718.1 | I34: =I31-I33 -> 814.7 | J34: =J31-J33 -> 850.77034 | K34: =K31-K33 -> 890.19628 | L34: =L31-L33 -> 931.41506 | M34: =M31-M33 -> 974.50704 | N34: =N31-N33 -> 1019.5561 | P34: =RATE($N$27-$I$27,0,I34,-N34) -> 0.045881986
B35: Less: depreciation | G35: -85 | H35: -90 | I35: -115.1 | J35: =J56*J42 -> -127.09679 | K35: =K56*K42 -> -132.85505 | L35: =L56*L42 -> -138.87062 | M35: =M56*M42 -> -145.15487 | N35: =N56*N42 -> -151.71966
B36: Less: amortization | G36: -0.5 | H36: -1.9 | I36: -3.4 | J36: =-J58 -> -4.5 | K36: =-K58 -> -4.6 | L36: =-L58 -> -4.7 | M36: =-M58 -> -4.8 | N36: =-N58 -> -4.9
B37: EBIT | G37: =SUM(G34:G36) -> 765.7 | H37: =SUM(H34:H36) -> 626.2 | I37: =SUM(I34:I36) -> 696.2 | J37: =SUM(J34:J36) -> 719.17355 | K37: =SUM(K34:K36) -> 752.74123 | L37: =SUM(L34:L36) -> 787.84444 | M37: =SUM(M34:M36) -> 824.55217 | N37: =SUM(N34:N36) -> 862.93645 | P37: =RATE($N$27-$I$27,0,I37,-N37) -> 0.04387611
B38: Less: taxes @ | E38: 0.38 | G38: =-G37*$E$38 -> -290.966 | H38: =-H37*$E$38 -> -237.956 | I38: =-I37*$E$38 -> -264.556 | J38: =-J37*$E$38 -> -273.28595 | K38: =-K37*$E$38 -> -286.04167 | L38: =-L37*$E$38 -> -299.38089 | M38: =-M37*$E$38 -> -313.32983 | N38: =-N37*$E$38 -> -327.91585
B39: Tax-effected EBIT | G39: =SUM(G37:G38) -> 474.734 | H39: =SUM(H37:H38) -> 388.244 | I39: =SUM(I37:I38) -> 431.644 | J39: =SUM(J37:J38) -> 445.8876 | K39: =SUM(K37:K38) -> 466.69956 | L39: =SUM(L37:L38) -> 488.46356 | M39: =SUM(M37:M38) -> 511.22235 | N39: =SUM(N37:N38) -> 535.0206 | P39: =RATE($N$27-$I$27,0,I39,-N39) -> 0.04387611
B41: Plus: depreciation & amortization | H41: =-(H35+H36) -> 91.9 | I41: =-(I35+I36) -> 118.5 | J41: =-(J35+J36) -> 131.59679 | K41: =-(K35+K36) -> 137.45505 | L41: =-(L35+L36) -> 143.57062 | M41: =-(M35+M36) -> 149.95487 | N41: =-(N35+N36) -> 156.61966
B42: Less: capital expenditures | H42: -95.8 | I42: -120.6 | J42: =-J55*J29 -> -129.6906 | K42: =-K55*K29 -> -134.87822 | L42: =-L55*L29 -> -140.27335 | M42: =-M55*M29 -> -145.88429 | N42: =-N55*N29 -> -151.71966
B43: Less: additions to intangibles | H43: -2 | I43: -4 | J43: =-J57 -> -5 | K43: =-K57 -> -5 | L43: =-L57 -> -5 | M43: =-M57 -> -5 | N43: =-N57 -> -5
B44: + / - Changes in working capital | H44: -19.2 | I44: -20 | J44: =J59*J29 -> -20.750496 | K44: =K59*K29 -> -21.580516 | L44: =L59*L29 -> -22.443736 | M44: =M59*M29 -> -23.341486 | N44: =N59*N29 -> -24.275145
A45: x | B45: Unlevered free cash flow | H45: =SUM(H39:H44) -> 363.144 | I45: =SUM(I39:I44) -> 405.544 | J45: =SUM(J39:J44) -> 422.04329 | K45: =SUM(K39:K44) -> 442.69587 | L45: =SUM(L39:L44) -> 464.31709 | M45: =SUM(M39:M44) -> 486.95144 | N45: =SUM(N39:N44) -> 510.64545 | P45: =RATE($N$27-$I$27,0,I45,-N45) -> 0.047167844
G48: Historical | J48: Projected
B49: Value Drivers | G49: =G27 -> 2013 | H49: =H27 -> 2014 | I49: =I27 -> 2015 | J49: =J27 -> 2016 | K49: =K27 -> 2017 | L49: =L27 -> 2018 | M49: =M27 -> 2019 | N49: =N27 -> 2020 | Q49: Step
S50: Cell Anchoring
...

Sheet DCF Solution
B1: =MID(CELL("filename",B1),FIND("]",CELL("filename",B1))+1,31) -> DCF Solution
D3: 1 | E3: =MID('Steps 1-2'!C3,9,100) -> Input the Unlevered Free Cash Flow line items | K3: Compound Annual Growth Rates (CAGRs)
D4: =D3+1 -> 2 | E4: =MID('Steps 1-2'!C8,9,100) -> Calculate the historical ratios and growth rates | K4: - Rate Function: RATE(nper,pmt, pv, [fv])
D5: =D4+1 -> 3 | E5: =MID('Steps 3-6'!C3,9,100) -> Forecast net sales for the projected years | K5: - Formula: | M5: (FV / PV) (1/N) -1
D6: =D5+1 -> 4 | E6: =MID('Steps 3-6'!C9,9,100) -> Project future operating expenses
D7: =D6+1 -> 5 | E7: =MID('Steps 3-6'!J3,9,100) -> Add ''steps'' to your assumptions | K7: Weighted Average Cost of Capital (WACC)
D8: =D7+1 -> 6 | E8: =MID('Steps 3-6'!J9,9,100) -> Calculate totals | L8: WACC = Ke x | M8: E + Kd x (1 + T) x D
D9: =D8+1 -> 7 | E9: =MID('Steps 7-10'!C3,9,100) -> Project Capital Expenditures & Depreciation | M9: D + E | N9: D + E
D10: =D9+1 -> 8 | E10: =MID('Steps 7-10'!C13,9,100) -> Project Additions to Intangibles & Amortization | K10: Present Value
D11: =D10+1 -> 9 | E11: =MID('Steps 7-10'!J3,9,100) -> Project future working capital requirements | K11: - NPV Function: NPV(rate,value1, value2, value3...)
D12: =D11+1 -> 10 | E12: =MID('Steps 7-10'!J7,10,100) -> Calculate Unlevered Free Cash Flow | K12: - Formula: | M12: CF1 + CF2 + … CFn
D13: =D12+1 -> 11 | E13: =MID('Steps 11-17'!C3,10,100) -> Calculate the net present value of the unlevered free cash flow | M13: (1+r)1 (1+r)2 (1+r)3
D14: =D13+1 -> 12 | E14: =MID('Steps 11-17'!C12,10,100) -> Calculate the terminal value | K14: - PV Function: PV(rate,nper, pmt, [fv])
D15: =D14+1 -> 13 | E15: =MID('Steps 11-17'!K3,10,100) -> Calculate the present value of terminal value
D16: =D15+1 -> 14 | E16: =MID('Steps 11-17'!K7,10,100) -> Calculate the Enterprise Value | K16: Enterprise Value
D17: =D16+1 -> 15 | E17: =MID('Steps 11-17'!K10,10,100) -> Calculate the Equity Value | K17: NPV of cash flows + PV of Terminal Value
D18: =D17+1 -> 16 | E18: =MID('Steps 11-17'!K14,10,100) -> Calculate the Equity Value per share
D19: =D18+1 -> 17 | E19: =MID('Steps 11-17'!K17,10,100) -> Sensitize the equity value per share | K19: =MID('Steps 11-17'!K12,FIND("-",'Steps 11-17'!K12)+2,100) -> Equity Value = Enterprise Value + "Net Debt"
B22: ="Discounted Cash Flow Analysis for "&Company -> Discounted Cash Flow Analysis for Sample Company
B23: =Subheader -> Dollars in millions, except per share
P25: =I27&" - "&N27 -> 2015 - 2020
G26: Historical | J26: Projected | P26: CAGR
G27: =H27-1 -> 2013 | H27: =I27-1 -> 2014 | I27: =YEAR(FYE) -> 2015 | J27: =I27+1 -> 2016 | K27: =J27+1 -> 2017 | L27: =K27+1 -> 2018 | M27: =L27+1 -> 2019 | N27: =M27+1 -> 2020
A29: x | B29: Sales | G29: 4666 | H29: 4791.9 | I29: 4988.1 | J29: =I29*(1+J51) -> 5187.624 | K29: =J29*(1+K51) -> 5395.129 | L29: =K29*(1+L51) -> 5610.9341 | M29: =L29*(1+M51) -> 5835.3715 | N29: =M29*(1+N51) -> 6068.7863 | P29: =RATE($N$27-$I$27,0,I29,-N29) -> 0.04
B30: Cost of goods sold | G30: 3498.8 | H30: 3767.7 | I30: 3893.1 | J30: =J29*J52 -> 4046.3467 | K30: =K29*K52 -> 4202.8055 | L30: =L29*L52 -> 4365.3067 | M30: =M29*M52 -> 4534.0836 | N30: =N29*N52 -> 4709.3782
B31: Gross profit | G31: =G29-G30 -> 1167.2 | H31: =H29-H30 -> 1024.2 | I31: =I29-I30 -> 1095 | J31: =J29-J30 -> 1141.2773 | K31: =K29-K30 -> 1192.3235 | L31: =L29-L30 -> 1245.6274 | M31: =M29-M30 -> 1301.2878 | N31: =N29-N30 -> 1359.4081 | P31: =RATE($N$27-$I$27,0,I31,-N31) -> 0.04420832
B33: Selling, general & administrative | G33: 316 | H33: 306.1 | I33: 280.3 | J33: =J29*J53 -> 290.50694 | K33: =K29*K53 -> 302.12722 | L33: =L29*L53 -> 314.21231 | M33: =M29*M53 -> 326.7808 | N33: =N29*N53 -> 339.85204
B34: EBITDA | G34: =G31-G33 -> 851.2 | H34: =H31-H33 -> 718.1 | I34: =I31-I33 -> 814.7 | J34: =J31-J33 -> 850.77034 | K34: =K31-K33 -> 890.19628 | L34: =L31-L33 -> 931.41506 | M34: =M31-M33 -> 974.50704 | N34: =N31-N33 -> 1019.5561 | P34: =RATE($N$27-$I$27,0,I34,-N34) -> 0.045881986
B35: Less: depreciation | G35: -85 | H35: -90 | I35: -115.1 | J35: =J56*J42 -> -127.09679 | K35: =K56*K42 -> -132.85505 | L35: =L56*L42 -> -138.87062 | M35: =M56*M42 -> -145.15487 | N35: =N56*N42 -> -151.71966
B36: Less: amortization | G36: -0.5 | H36: -1.9 | I36: -3.4 | J36: =-J58 -> -4.5 | K36: =-K58 -> -4.6 | L36: =-L58 -> -4.7 | M36: =-M58 -> -4.8 | N36: =-N58 -> -4.9
B37: EBIT | G37: =SUM(G34:G36) -> 765.7 | H37: =SUM(H34:H36) -> 626.2 | I37: =SUM(I34:I36) -> 696.2 | J37: =SUM(J34:J36) -> 719.17355 | K37: =SUM(K34:K36) -> 752.74123 | L37: =SUM(L34:L36) -> 787.84444 | M37: =SUM(M34:M36) -> 824.55217 | N37: =SUM(N34:N36) -> 862.93645 | P37: =RATE($N$27-$I$27,0,I37,-N37) -> 0.04387611
B38: Less: taxes @ | E38: 0.38 | G38: =-G37*$E$38 -> -290.966 | H38: =-H37*$E$38 -> -237.956 | I38: =-I37*$E$38 -> -264.556 | J38: =-J37*$E$38 -> -273.28595 | K38: =-K37*$E$38 -> -286.04167 | L38: =-L37*$E$38 -> -299.38089 | M38: =-M37*$E$38 -> -313.32983 | N38: =-N37*$E$38 -> -327.91585
A39: x | B39: Tax-effected EBIT | G39: =SUM(G37:G38) -> 474.734 | H39: =SUM(H37:H38) -> 388.244 | I39: =SUM(I37:I38) -> 431.644 | J39: =SUM(J37:J38) -> 445.8876 | K39: =SUM(K37:K38) -> 466.69956 | L39: =SUM(L37:L38) -> 488.46356 | M39: =SUM(M37:M38) -> 511.22235 | N39: =SUM(N37:N38) -> 535.0206 | P39: =RATE($N$27-$I$27,0,I39,-N39) -> 0.04387611
B41: Plus: depreciation & amortization | H41: =-(H35+H36) -> 91.9 | I41: =-(I35+I36) -> 118.5 | J41: =-(J35+J36) -> 131.59679 | K41: =-(K35+K36) -> 137.45505 | L41: =-(L35+L36) -> 143.57062 | M41: =-(M35+M36) -> 149.95487 | N41: =-(N35+N36) -> 156.61966
B42: Less: capital expenditures | H42: -95.8 | I42: -120.6 | J42: =-J55*J29 -> -129.6906 | K42: =-K55*K29 -> -134.87822 | L42: =-L55*L29 -> -140.27335 | M42: =-M55*M29 -> -145.88429 | N42: =-N55*N29 -> -151.71966
B43: Less: additions to intangibles | H43: -2 | I43: -4 | J43: =-J57 -> -5 | K43: =-K57 -> -5 | L43: =-L57 -> -5 | M43: =-M57 -> -5 | N43: =-N57 -> -5
B44: + / - Changes in working capital | H44: -19.2 | I44: -20 | J44: =J59*J29 -> -20.750496 | K44: =K59*K29 -> -21.580516 | L44: =L59*L29 -> -22.443736 | M44: =M59*M29 -> -23.341486 | N44: =N59*N29 -> -24.275145
A45: x | B45: Unlevered free cash flow | H45: =SUM(H39:H44) -> 363.144 | I45: =SUM(I39:I44) -> 405.544 | J45: =SUM(J39:J44) -> 422.04329 | K45: =SUM(K39:K44) -> 442.69587 | L45: =SUM(L39:L44) -> 464.31709 | M45: =SUM(M39:M44) -> 486.95144 | N45: =SUM(N39:N44) -> 510.64545 | P45: =RATE($N$27-$I$27,0,I45,-N45) -> 0.047167844
G48: Historical | J48: Projected
B49: Value Drivers | G49: =G27 -> 2013 | H49: =H27 -> 2014 | I49: =I27 -> 2015 | J49: =J27 -> 2016 | K49: =K27 -> 2017 | L49: =L27 -> 2018 | M49: =M27 -> 2019 | N49: =N27 -> 2020 | Q49: Step
...

Sheet DCF Template
B1: =MID(CELL("filename",B1),FIND("]",CELL("filename",B1))+1,31) -> DCF Template
D3: 1 | E3: =MID('Steps 1-2'!C3,9,100) -> Input the Unlevered Free Cash Flow line items | K3: Compound Annual Growth Rates (CAGRs)
D4: =D3+1 -> 2 | E4: =MID('Steps 1-2'!C8,9,100) -> Calculate the historical ratios and growth rates | K4: - Rate Function: RATE(nper,pmt, pv, [fv])
D5: =D4+1 -> 3 | E5: =MID('Steps 3-6'!C3,9,100) -> Forecast net sales for the projected years | K5: - Formula: | M5: (FV / PV) (1/N) -1
D6: =D5+1 -> 4 | E6: =MID('Steps 3-6'!C9,9,100) -> Project future operating expenses
D7: =D6+1 -> 5 | E7: =MID('Steps 3-6'!J3,9,100) -> Add ''steps'' to your assumptions | K7: Weighted Average Cost of Capital (WACC)
D8: =D7+1 -> 6 | E8: =MID('Steps 3-6'!J9,9,100) -> Calculate totals | L8: WACC = Ke x | M8: E + Kd x (1 + T) x D
D9: =D8+1 -> 7 | E9: =MID('Steps 7-10'!C3,9,100) -> Project Capital Expenditures & Depreciation | M9: D + E | N9: D + E
D10: =D9+1 -> 8 | E10: =MID('Steps 7-10'!C13,9,100) -> Project Additions to Intangibles & Amortization | K10: Present Value
D11: =D10+1 -> 9 | E11: =MID('Steps 7-10'!J3,9,100) -> Project future working capital requirements | K11: - NPV Function: NPV(rate,value1, value2, value3...)
D12: =D11+1 -> 10 | E12: =MID('Steps 7-10'!J7,10,100) -> Calculate Unlevered Free Cash Flow | K12: - Formula: | M12: CF1 + CF2 + … CFn
D13: =D12+1 -> 11 | E13: =MID('Steps 11-17'!C3,10,100) -> Calculate the net present value of the unlevered free cash flow | M13: (1+r)1 (1+r)2 (1+r)3
D14: =D13+1 -> 12 | E14: =MID('Steps 11-17'!C12,10,100) -> Calculate the terminal value | K14: - PV Function: PV(rate,nper, pmt, [fv])
D15: =D14+1 -> 13 | E15: =MID('Steps 11-17'!K3,10,100) -> Calculate the present value of terminal value
D16: =D15+1 -> 14 | E16: =MID('Steps 11-17'!K7,10,100) -> Calculate the Enterprise Value | K16: Enterprise Value
D17: =D16+1 -> 15 | E17: =MID('Steps 11-17'!K10,10,100) -> Calculate the Equity Value | K17: NPV of cash flows + PV of Terminal Value
D18: =D17+1 -> 16 | E18: =MID('Steps 11-17'!K14,10,100) -> Calculate the Equity Value per share
D19: =D18+1 -> 17 | E19: =MID('Steps 11-17'!K17,10,100) -> Sensitize the equity value per share | K19: =MID('Steps 11-17'!K12,FIND("-",'Steps 11-17'!K12)+2,100) -> Equity Value = Enterprise Value + "Net Debt"
B22: ="Discounted Cash Flow Analysis for "&T25 -> Discounted Cash Flow Analysis for Sample Company
B23: =T31 -> Dollars in millions, except per share
T24: Company Name
P25: =I27&" - "&N27 -> 2015 - 2020 | T25: Sample Company
G26: Historical | J26: Projected | P26: CAGR
G27: =H27-1 -> 2013 | H27: =I27-1 -> 2014 | I27: =YEAR(T28) -> 2015 | J27: =I27+1 -> 2016 | K27: =J27+1 -> 2017 | L27: =K27+1 -> 2018 | M27: =L27+1 -> 2019 | N27: =M27+1 -> 2020 | T27: Last Fiscal Year End
T28: 42369
A29: x | B29: Sales | G29: 0 | H29: 0 | I29: 0 | J29: =I29*(1+J51) -> 0 | K29: =J29*(1+K51) -> 0 | L29: =K29*(1+L51) -> 0 | M29: =L29*(1+M51) -> 0 | N29: =M29*(1+N51) -> 0 | P29: =IF(I29=0,"",RATE($N$27-$I$27,0,I29,-N29))
B30: Cost of goods sold | G30: 0 | H30: 0 | I30: 0 | J30: =J29*J52 -> 0 | K30: =K29*K52 -> 0 | L30: =L29*L52 -> 0 | M30: =M29*M52 -> 0 | N30: =N29*N52 -> 0 | T30: Subheader
B31: Gross profit | G31: =G29-G30 -> 0 | H31: =H29-H30 -> 0 | I31: =I29-I30 -> 0 | J31: =J29-J30 -> 0 | K31: =K29-K30 -> 0 | L31: =L29-L30 -> 0 | M31: =M29-M30 -> 0 | N31: =N29-N30 -> 0 | P31: =IF(I31=0,"",RATE($N$27-$I$27,0,I31,-N31)) | T31: Dollars in millions, except per share
B33: Selling, general & administrative | G33: 0 | H33: 0 | I33: 0 | J33: =J29*J53 -> 0 | K33: =K29*K53 -> 0 | L33: =L29*L53 -> 0 | M33: =M29*M53 -> 0 | N33: =N29*N53 -> 0
B34: EBITDA | G34: =G31-G33 -> 0 | H34: =H31-H33 -> 0 | I34: =I31-I33 -> 0 | J34: =J31-J33 -> 0 | K34: =K31-K33 -> 0 | L34: =L31-L33 -> 0 | M34: =M31-M33 -> 0 | N34: =N31-N33 -> 0 | P34: =IF(I34=0,"",RATE($N$27-$I$27,0,I34,-N34))
B35: Less: depreciation | G35: 0 | H35: 0 | I35: 0 | J35: =J56*J42 -> 0 | K35: =K56*K42 -> 0 | L35: =L56*L42 -> 0 | M35: =M56*M42 -> 0 | N35: =N56*N42 -> 0
B36: Less: amortization | G36: 0 | H36: 0 | I36: 0 | J36: =-J58 -> 0 | K36: =-K58 -> 0 | L36: =-L58 -> 0 | M36: =-M58 -> 0 | N36: =-N58 -> 0
B37: EBIT | G37: =SUM(G34:G36) -> 0 | H37: =SUM(H34:H36) -> 0 | I37: =SUM(I34:I36) -> 0 | J37: =SUM(J34:J36) -> 0 | K37: =SUM(K34:K36) -> 0 | L37: =SUM(L34:L36) -> 0 | M37: =SUM(M34:M36) -> 0 | N37: =SUM(N34:N36) -> 0 | P37: =IF(I37=0,"",RATE($N$27-$I$27,0,I37,-N37))
B38: Less: taxes @ | E38: 0.38 | G38: =-G37*$E$38 -> 0 | H38: =-H37*$E$38 -> 0 | I38: =-I37*$E$38 -> 0 | J38: =-J37*$E$38 -> 0 | K38: =-K37*$E$38 -> 0 | L38: =-L37*$E$38 -> 0 | M38: =-M37*$E$38 -> 0 | N38: =-N37*$E$38 -> 0
A39: x | B39: Tax-effected EBIT | G39: =SUM(G37:G38) -> 0 | H39: =SUM(H37:H38) -> 0 | I39: =SUM(I37:I38) -> 0 | J39: =SUM(J37:J38) -> 0 | K39: =SUM(K37:K38) -> 0 | L39: =SUM(L37:L38) -> 0 | M39: =SUM(M37:M38) -> 0 | N39: =SUM(N37:N38) -> 0 | P39: =IF(I39=0,"",RATE($N$27-$I$27,0,I39,-N39))
B41: Plus: depreciation & amortization | H41: =-(H35+H36) -> 0 | I41: =-(I35+I36) -> 0 | J41: =-(J35+J36) -> 0 | K41: =-(K35+K36) -> 0 | L41: =-(L35+L36) -> 0 | M41: =-(M35+M36) -> 0 | N41: =-(N35+N36) -> 0
B42: Less: capital expenditures | H42: 0 | I42: 0 | J42: =-J55*J29 -> 0 | K42: =-K55*K29 -> 0 | L42: =-L55*L29 -> 0 | M42: =-M55*M29 -> 0 | N42: =-N55*N29 -> 0
B43: Less: additions to intangibles | H43: 0 | I43: 0 | J43: =-J57 -> 0 | K43: =-K57 -> 0 | L43: =-L57 -> 0 | M43: =-M57 -> 0 | N43: =-N57 -> 0
B44: + / - Changes in working capital | H44: 0 | I44: 0 | J44: =J59*J29 -> 0 | K44: =K59*K29 -> 0 | L44: =L59*L29 -> 0 | M44: =M59*M29 -> 0 | N44: =N59*N29 -> 0
A45: x | B45: Unlevered free cash flow | H45: =SUM(H39:H44) -> 0 | I45: =SUM(I39:I44) -> 0 | J45: =SUM(J39:J44) -> 0 | K45: =SUM(K39:K44) -> 0 | L45: =SUM(L39:L44) -> 0 | M45: =SUM(M39:M44) -> 0 | N45: =SUM(N39:N44) -> 0 | P45: =IF(I45=0,"",RATE($N$27-$I$27,0,I45,-N45))
...
